Workbook

Sheet DATA & ASSUMPTIONS
A1: KAPPA FOUNDATION
A2: INPUT | B2: VALUE | C2: UNIT | D2: NOTE
A3: Initial Fund | B3: 12000000 | C3: USD
A4: 2024 Liability | B4: 2400000 | C4: USD | D4: 45657
A5: 2027 Liability | B5: 3600000 | C5: USD | D5: 46752
A6: 2030 Real-value Goal | B6: 8000000 | C6: USD | D6: USD in 2022 purchasing power
A7: Decision Date | B7: 44926
A8: Trustee Loss Concern | B8: 0.15 | D8: Approx.loss level
A9: Allowed Instruments | B9: Cash; 5 case bonds; US common stocks; US-listed ETFs primarily in US equities
A10: Prohibited | B10: Borrowing; short salesl derivatives
A11: Bond Coupon Convention | B11: Annual coupons on 31 December
A13: BOND DATA
A14: Bond | B14: Maturity | C14: Coupon | D14: Coupon Frequency | E14: Price per 1000 USD | F14: Note
A15: Alpha | B15: 1 | C15: 0 | D15: None/ Zero-coupon | E15: 958.77
A16: Beta | B16: 2 | C16: 0 | D16: None/ Zero-coupon | E16: 922.78
A17: Gamma | B17: 3 | C17: 0.04 | D17: Annual | E17: 1002.49 | F17: Coupon = $40/year
A18: Delta | B18: 5 | C18: 0.035 | D18: Annual | E18: 986.07 | F18: Coupon = $35/year
A19: Epsilon | B19: 8 | C19: 0.045 | D19: Annual | E19: 1040.71 | F19: Coupon = $45/ year
A21: POLICY ASSUMPTIONS
A22: Assumption | B22: Base Case | C22: Scenario 1 | D22: Scenario 2 | E22: Source / Rationale | F22: Status
A23: Inflation assumption | B23: 0.023 | C23: 0.02 | D23: 0.04 | E23: FRED 10Y Breakeven, 30-Dec-2022 = 2.30%; market reference, not an 8-year forecast. https://fred.stlouisfed.org/series/T10YIE | F23: PROPOSED
A24: Risk aversion A | B24: 3 | C24: 3 | D24: 6 | E24: A=3 base case; A=6 higher-risk-aversion sensitivity. Utility comparison requires integrated portfolio outputs from Mem 2. | F24: APPROVE
A25: Cash buffer | B25: 0 | C25: 0 | D25: 250000 | E25: No compulsory minimum in the case; $0 base case and $250k liquidity stress. | F25: OPEN
A26: Parallel Rate Shock | B26: 0.01 | C26: -0.01 | D26: 0.01 | E26: Illustrative ±100 bps parallel shock; stress-test design, not a forecast. | F26: PROPOSED
A27: 2Y Curve Shock | B27: 0.005 | C27: -0.005 | D27: 0.005 | E27: Illustrative short-end shock for Beta / 2024 funding. | F27: PROPOSED
A28: 5Y Curve Shock | B28: -0.005 | C28: -0.0025 | D28: 0.0025 | E28: Illustrative 5Y shock for Delta / 2027 funding. | F28: PROPOSED
A29: Term Structure Treatment | B29: Assume 4Y spot = 3Y spot (flat 3Y- 4Y segment) | C29: 4Y spot -0.25% | D29: 4Y spot +0.25% | E29: 4Y spot is not identified by the case; use an explicit assumption, then derive 5Y from Delta. | F29: PROPOSED
A30: OBJECTIVE
A31: Fund the 2024 and 2027 contractual liabilities first, then determine the residual capital available for the growth portfolio while considering Kappa’s risk tolerance and 2030 real purchasing-power objective.

Sheet BOND & FUNDING ANALYSIS
A1: BOND CASH-FLOW ( PER $1,000 FACE VALUE)
A2: Bond | B2: 2023 | C2: 2024 | D2: 2025 | E2: 2026 | F2: 2027 | G2: 2028 | H2: 2029 | I2: 2030 | J2: Total CF | K2: Funding Role
A3: Alpha | B3: =IF(B$2-2022<VALUE(LEFT('DATA & ASSUMPTIONS'!$B15,1)),1000*'DATA & ASSUMPTIONS'!$C15,IF(B$2-2022=VALUE(LEFT('DATA & ASSUMPTIONS'!$B15,1)),1000*(1+'DATA & ASSUMPTIONS'!$C15),0)) -> 1000 | C3: =IF(C$2-2022<VALUE(LEFT('DATA & ASSUMPTIONS'!$B15,1)),1000*'DATA & ASSUMPTIONS'!$C15,IF(C$2-2022=VALUE(LEFT('DATA & ASSUMPTIONS'!$B15,1)),1000*(1+'DATA & ASSUMPTIONS'!$C15),0)) -> 0 | D3: =IF(D$2-2022<VALUE(LEFT('DATA & ASSUMPTIONS'!$B15,1)),1000*'DATA & ASSUMPTIONS'!$C15,IF(D$2-2022=VALUE(LEFT('DATA & ASSUMPTIONS'!$B15,1)),1000*(1+'DATA & ASSUMPTIONS'!$C15),0)) -> 0 | E3: =IF(E$2-2022<VALUE(LEFT('DATA & ASSUMPTIONS'!$B15,1)),1000*'DATA & ASSUMPTIONS'!$C15,IF(E$2-2022=VALUE(LEFT('DATA & ASSUMPTIONS'!$B15,1)),1000*(1+'DATA & ASSUMPTIONS'!$C15),0)) -> 0 | F3: =IF(F$2-2022<VALUE(LEFT('DATA & ASSUMPTIONS'!$B15,1)),1000*'DATA & ASSUMPTIONS'!$C15,IF(F$2-2022=VALUE(LEFT('DATA & ASSUMPTIONS'!$B15,1)),1000*(1+'DATA & ASSUMPTIONS'!$C15),0)) -> 0 | G3: =IF(G$2-2022<VALUE(LEFT('DATA & ASSUMPTIONS'!$B15,1)),1000*'DATA & ASSUMPTIONS'!$C15,IF(G$2-2022=VALUE(LEFT('DATA & ASSUMPTIONS'!$B15,1)),1000*(1+'DATA & ASSUMPTIONS'!$C15),0)) -> 0 | H3: =IF(H$2-2022<VALUE(LEFT('DATA & ASSUMPTIONS'!$B15,1)),1000*'DATA & ASSUMPTIONS'!$C15,IF(H$2-2022=VALUE(LEFT('DATA & ASSUMPTIONS'!$B15,1)),1000*(1+'DATA & ASSUMPTIONS'!$C15),0)) -> 0 | I3: =IF(I$2-2022<VALUE(LEFT('DATA & ASSUMPTIONS'!$B15,1)),1000*'DATA & ASSUMPTIONS'!$C15,IF(I$2-2022=VALUE(LEFT('DATA & ASSUMPTIONS'!$B15,1)),1000*(1+'DATA & ASSUMPTIONS'!$C15),0)) -> 0 | J3: =SUM(B3:I3) -> 1000 | K3: 1Y maturity / reference zero-coupon
A4: Beta | B4: =IF(B$2-2022<VALUE(LEFT('DATA & ASSUMPTIONS'!$B16,1)),1000*'DATA & ASSUMPTIONS'!$C16,IF(B$2-2022=VALUE(LEFT('DATA & ASSUMPTIONS'!$B16,1)),1000*(1+'DATA & ASSUMPTIONS'!$C16),0)) -> 0 | C4: =IF(C$2-2022<VALUE(LEFT('DATA & ASSUMPTIONS'!$B16,1)),1000*'DATA & ASSUMPTIONS'!$C16,IF(C$2-2022=VALUE(LEFT('DATA & ASSUMPTIONS'!$B16,1)),1000*(1+'DATA & ASSUMPTIONS'!$C16),0)) -> 1000 | D4: =IF(D$2-2022<VALUE(LEFT('DATA & ASSUMPTIONS'!$B16,1)),1000*'DATA & ASSUMPTIONS'!$C16,IF(D$2-2022=VALUE(LEFT('DATA & ASSUMPTIONS'!$B16,1)),1000*(1+'DATA & ASSUMPTIONS'!$C16),0)) -> 0 | E4: =IF(E$2-2022<VALUE(LEFT('DATA & ASSUMPTIONS'!$B16,1)),1000*'DATA & ASSUMPTIONS'!$C16,IF(E$2-2022=VALUE(LEFT('DATA & ASSUMPTIONS'!$B16,1)),1000*(1+'DATA & ASSUMPTIONS'!$C16),0)) -> 0 | F4: =IF(F$2-2022<VALUE(LEFT('DATA & ASSUMPTIONS'!$B16,1)),1000*'DATA & ASSUMPTIONS'!$C16,IF(F$2-2022=VALUE(LEFT('DATA & ASSUMPTIONS'!$B16,1)),1000*(1+'DATA & ASSUMPTIONS'!$C16),0)) -> 0 | G4: =IF(G$2-2022<VALUE(LEFT('DATA & ASSUMPTIONS'!$B16,1)),1000*'DATA & ASSUMPTIONS'!$C16,IF(G$2-2022=VALUE(LEFT('DATA & ASSUMPTIONS'!$B16,1)),1000*(1+'DATA & ASSUMPTIONS'!$C16),0)) -> 0 | H4: =IF(H$2-2022<VALUE(LEFT('DATA & ASSUMPTIONS'!$B16,1)),1000*'DATA & ASSUMPTIONS'!$C16,IF(H$2-2022=VALUE(LEFT('DATA & ASSUMPTIONS'!$B16,1)),1000*(1+'DATA & ASSUMPTIONS'!$C16),0)) -> 0 | I4: =IF(I$2-2022<VALUE(LEFT('DATA & ASSUMPTIONS'!$B16,1)),1000*'DATA & ASSUMPTIONS'!$C16,IF(I$2-2022=VALUE(LEFT('DATA & ASSUMPTIONS'!$B16,1)),1000*(1+'DATA & ASSUMPTIONS'!$C16),0)) -> 0 | J4: =SUM(B4:I4) -> 1000 | K4: Candidate 2024 liability match
A5: Gamma | B5: =IF(B$2-2022<VALUE(LEFT('DATA & ASSUMPTIONS'!$B17,1)),1000*'DATA & ASSUMPTIONS'!$C17,IF(B$2-2022=VALUE(LEFT('DATA & ASSUMPTIONS'!$B17,1)),1000*(1+'DATA & ASSUMPTIONS'!$C17),0)) -> 40 | C5: =IF(C$2-2022<VALUE(LEFT('DATA & ASSUMPTIONS'!$B17,1)),1000*'DATA & ASSUMPTIONS'!$C17,IF(C$2-2022=VALUE(LEFT('DATA & ASSUMPTIONS'!$B17,1)),1000*(1+'DATA & ASSUMPTIONS'!$C17),0)) -> 40 | D5: =IF(D$2-2022<VALUE(LEFT('DATA & ASSUMPTIONS'!$B17,1)),1000*'DATA & ASSUMPTIONS'!$C17,IF(D$2-2022=VALUE(LEFT('DATA & ASSUMPTIONS'!$B17,1)),1000*(1+'DATA & ASSUMPTIONS'!$C17),0)) -> 1040 | E5: =IF(E$2-2022<VALUE(LEFT('DATA & ASSUMPTIONS'!$B17,1)),1000*'DATA & ASSUMPTIONS'!$C17,IF(E$2-2022=VALUE(LEFT('DATA & ASSUMPTIONS'!$B17,1)),1000*(1+'DATA & ASSUMPTIONS'!$C17),0)) -> 0 | F5: =IF(F$2-2022<VALUE(LEFT('DATA & ASSUMPTIONS'!$B17,1)),1000*'DATA & ASSUMPTIONS'!$C17,IF(F$2-2022=VALUE(LEFT('DATA & ASSUMPTIONS'!$B17,1)),1000*(1+'DATA & ASSUMPTIONS'!$C17),0)) -> 0 | G5: =IF(G$2-2022<VALUE(LEFT('DATA & ASSUMPTIONS'!$B17,1)),1000*'DATA & ASSUMPTIONS'!$C17,IF(G$2-2022=VALUE(LEFT('DATA & ASSUMPTIONS'!$B17,1)),1000*(1+'DATA & ASSUMPTIONS'!$C17),0)) -> 0 | H5: =IF(H$2-2022<VALUE(LEFT('DATA & ASSUMPTIONS'!$B17,1)),1000*'DATA & ASSUMPTIONS'!$C17,IF(H$2-2022=VALUE(LEFT('DATA & ASSUMPTIONS'!$B17,1)),1000*(1+'DATA & ASSUMPTIONS'!$C17),0)) -> 0 | I5: =IF(I$2-2022<VALUE(LEFT('DATA & ASSUMPTIONS'!$B17,1)),1000*'DATA & ASSUMPTIONS'!$C17,IF(I$2-2022=VALUE(LEFT('DATA & ASSUMPTIONS'!$B17,1)),1000*(1+'DATA & ASSUMPTIONS'!$C17),0)) -> 0 | J5: =SUM(B5:I5) -> 1120 | K5: 3Y coupon bond / curve information
A6: Delta | B6: =IF(B$2-2022<VALUE(LEFT('DATA & ASSUMPTIONS'!$B18,1)),1000*'DATA & ASSUMPTIONS'!$C18,IF(B$2-2022=VALUE(LEFT('DATA & ASSUMPTIONS'!$B18,1)),1000*(1+'DATA & ASSUMPTIONS'!$C18),0)) -> 35 | C6: =IF(C$2-2022<VALUE(LEFT('DATA & ASSUMPTIONS'!$B18,1)),1000*'DATA & ASSUMPTIONS'!$C18,IF(C$2-2022=VALUE(LEFT('DATA & ASSUMPTIONS'!$B18,1)),1000*(1+'DATA & ASSUMPTIONS'!$C18),0)) -> 35 | D6: =IF(D$2-2022<VALUE(LEFT('DATA & ASSUMPTIONS'!$B18,1)),1000*'DATA & ASSUMPTIONS'!$C18,IF(D$2-2022=VALUE(LEFT('DATA & ASSUMPTIONS'!$B18,1)),1000*(1+'DATA & ASSUMPTIONS'!$C18),0)) -> 35 | E6: =IF(E$2-2022<VALUE(LEFT('DATA & ASSUMPTIONS'!$B18,1)),1000*'DATA & ASSUMPTIONS'!$C18,IF(E$2-2022=VALUE(LEFT('DATA & ASSUMPTIONS'!$B18,1)),1000*(1+'DATA & ASSUMPTIONS'!$C18),0)) -> 35 | F6: =IF(F$2-2022<VALUE(LEFT('DATA & ASSUMPTIONS'!$B18,1)),1000*'DATA & ASSUMPTIONS'!$C18,IF(F$2-2022=VALUE(LEFT('DATA & ASSUMPTIONS'!$B18,1)),1000*(1+'DATA & ASSUMPTIONS'!$C18),0)) -> 1035 | G6: =IF(G$2-2022<VALUE(LEFT('DATA & ASSUMPTIONS'!$B18,1)),1000*'DATA & ASSUMPTIONS'!$C18,IF(G$2-2022=VALUE(LEFT('DATA & ASSUMPTIONS'!$B18,1)),1000*(1+'DATA & ASSUMPTIONS'!$C18),0)) -> 0 | H6: =IF(H$2-2022<VALUE(LEFT('DATA & ASSUMPTIONS'!$B18,1)),1000*'DATA & ASSUMPTIONS'!$C18,IF(H$2-2022=VALUE(LEFT('DATA & ASSUMPTIONS'!$B18,1)),1000*(1+'DATA & ASSUMPTIONS'!$C18),0)) -> 0 | I6: =IF(I$2-2022<VALUE(LEFT('DATA & ASSUMPTIONS'!$B18,1)),1000*'DATA & ASSUMPTIONS'!$C18,IF(I$2-2022=VALUE(LEFT('DATA & ASSUMPTIONS'!$B18,1)),1000*(1+'DATA & ASSUMPTIONS'!$C18),0)) -> 0 | J6: =SUM(B6:I6) -> 1175 | K6: Candidate 2027 liability match
A7: Epsilon | B7: =IF(B$2-2022<VALUE(LEFT('DATA & ASSUMPTIONS'!$B19,1)),1000*'DATA & ASSUMPTIONS'!$C19,IF(B$2-2022=VALUE(LEFT('DATA & ASSUMPTIONS'!$B19,1)),1000*(1+'DATA & ASSUMPTIONS'!$C19),0)) -> 45 | C7: =IF(C$2-2022<VALUE(LEFT('DATA & ASSUMPTIONS'!$B19,1)),1000*'DATA & ASSUMPTIONS'!$C19,IF(C$2-2022=VALUE(LEFT('DATA & ASSUMPTIONS'!$B19,1)),1000*(1+'DATA & ASSUMPTIONS'!$C19),0)) -> 45 | D7: =IF(D$2-2022<VALUE(LEFT('DATA & ASSUMPTIONS'!$B19,1)),1000*'DATA & ASSUMPTIONS'!$C19,IF(D$2-2022=VALUE(LEFT('DATA & ASSUMPTIONS'!$B19,1)),1000*(1+'DATA & ASSUMPTIONS'!$C19),0)) -> 45 | E7: =IF(E$2-2022<VALUE(LEFT('DATA & ASSUMPTIONS'!$B19,1)),1000*'DATA & ASSUMPTIONS'!$C19,IF(E$2-2022=VALUE(LEFT('DATA & ASSUMPTIONS'!$B19,1)),1000*(1+'DATA & ASSUMPTIONS'!$C19),0)) -> 45 | F7: =IF(F$2-2022<VALUE(LEFT('DATA & ASSUMPTIONS'!$B19,1)),1000*'DATA & ASSUMPTIONS'!$C19,IF(F$2-2022=VALUE(LEFT('DATA & ASSUMPTIONS'!$B19,1)),1000*(1+'DATA & ASSUMPTIONS'!$C19),0)) -> 45 | G7: =IF(G$2-2022<VALUE(LEFT('DATA & ASSUMPTIONS'!$B19,1)),1000*'DATA & ASSUMPTIONS'!$C19,IF(G$2-2022=VALUE(LEFT('DATA & ASSUMPTIONS'!$B19,1)),1000*(1+'DATA & ASSUMPTIONS'!$C19),0)) -> 45 | H7: =IF(H$2-2022<VALUE(LEFT('DATA & ASSUMPTIONS'!$B19,1)),1000*'DATA & ASSUMPTIONS'!$C19,IF(H$2-2022=VALUE(LEFT('DATA & ASSUMPTIONS'!$B19,1)),1000*(1+'DATA & ASSUMPTIONS'!$C19),0)) -> 45 | I7: =IF(I$2-2022<VALUE(LEFT('DATA & ASSUMPTIONS'!$B19,1)),1000*'DATA & ASSUMPTIONS'!$C19,IF(I$2-2022=VALUE(LEFT('DATA & ASSUMPTIONS'!$B19,1)),1000*(1+'DATA & ASSUMPTIONS'!$C19),0)) -> 1045 | J7: =SUM(B7:I7) -> 1360 | K7: Longer maturity / rate-risk comparison
A10: BOND VALUATION & YTM
A11: Bond | B11: Price Input | C11: Face Value | D11: Coupon Rate | E11: Maturity | F11: Annual Coupon | G11: YTM (Annual) | H11: Price Check YTM
A12: Alpha | B12: ='DATA & ASSUMPTIONS'!E15 -> 958.77 | C12: 1000 | D12: ='DATA & ASSUMPTIONS'!C15 -> 0 | E12: ='DATA & ASSUMPTIONS'!B15 -> 1 | F12: =C12*D12 -> 0 | G12: =RATE(E12,F12,-B12,C12) -> 0.043003014 | H12: =B3/(1+G12)^1+C3/(1+G12)^2+D3/(1+G12)^3+E3/(1+G12)^4+F3/(1+G12)^5+G3/(1+G12)^6+H3/(1+G12)^7+I3/(1+G12)^8 -> 958.77
A13: Beta | B13: ='DATA & ASSUMPTIONS'!E16 -> 922.78 | C13: 1000 | D13: ='DATA & ASSUMPTIONS'!C16 -> 0 | E13: ='DATA & ASSUMPTIONS'!B16 -> 2 | F13: =C13*D13 -> 0 | G13: =RATE(E13,F13,-B13,C13) -> 0.041000441 | H13: =B4/(1+G13)^1+C4/(1+G13)^2+D4/(1+G13)^3+E4/(1+G13)^4+F4/(1+G13)^5+G4/(1+G13)^6+H4/(1+G13)^7+I4/(1+G13)^8 -> 922.78
A14: Gamma | B14: ='DATA & ASSUMPTIONS'!E17 -> 1002.49 | C14: 1000 | D14: ='DATA & ASSUMPTIONS'!C17 -> 0.04 | E14: ='DATA & ASSUMPTIONS'!B17 -> 3 | F14: =C14*D14 -> 40 | G14: =RATE(E14,F14,-B14,C14) -> 0.039104257 | H14: =B5/(1+G14)^1+C5/(1+G14)^2+D5/(1+G14)^3+E5/(1+G14)^4+F5/(1+G14)^5+G5/(1+G14)^6+H5/(1+G14)^7+I5/(1+G14)^8 -> 1002.49
A15: Delta | B15: ='DATA & ASSUMPTIONS'!E18 -> 986.07 | C15: 1000 | D15: ='DATA & ASSUMPTIONS'!C18 -> 0.035 | E15: ='DATA & ASSUMPTIONS'!B18 -> 5 | F15: =C15*D15 -> 35 | G15: =RATE(E15,F15,-B15,C15) -> 0.038112483 | H15: =B6/(1+G15)^1+C6/(1+G15)^2+D6/(1+G15)^3+E6/(1+G15)^4+F6/(1+G15)^5+G6/(1+G15)^6+H6/(1+G15)^7+I6/(1+G15)^8 -> 986.07
A16: Epsilon | B16: ='DATA & ASSUMPTIONS'!E19 -> 1040.71 | C16: 1000 | D16: ='DATA & ASSUMPTIONS'!C19 -> 0.045 | E16: ='DATA & ASSUMPTIONS'!B19 -> 8 | F16: =C16*D16 -> 45 | G16: =RATE(E16,F16,-B16,C16) -> 0.038978901 | H16: =B7/(1+G16)^1+C7/(1+G16)^2+D7/(1+G16)^3+E7/(1+G16)^4+F7/(1+G16)^5+G7/(1+G16)^6+H7/(1+G16)^7+I7/(1+G16)^8 -> 1040.71
A19: TERM STRUCTURE / SPOT RATE CURVE
A20: Maturity (Year) | B20: Spot Rate | C20: Treatment
A21: 1 | B21: =$C$12/$B$12-1 -> 0.043003014 | C21: Alpha zero-coupon – directly implied
A22: 2 | B22: =($C$13/$B$13)^(1/2)-1 -> 0.041000441 | C22: Beta zero-coupon – directly implied
A23: 3 | B23: =((($C$14+$F$14)/($B$14-$F$14/(1+$B$21)-$F$14/(1+$B$22)^2))^(1/3))-1 -> 0.039000127 | C23: Bootstrapped from Gamma using exact 1Y and 2Y spot rates
A24: 4 | B24: =$B$23 -> 0.039000127 | C24: Assumption: s4 = s3 (flat 3Y– 4Y segment)
A25: 5 | B25: =((($C$15+$F$15)/($B$15-$F$15/(1+$B$21)-$F$15/(1+$B$22)^2-$F$15/(1+$B$23)^3-$F$15/(1+$B$24)^4))^(1/5))-1 -> 0.037986521 | C25: Derived from Delta after applying the 4Y assumption
A28: FUNDING PLAN
A29: CANDIDATE A - Maturity-Matched Strategy
A30: Liability | B30: Due Date | C30: Instrument | D30: Face / Unit | E30: Units | F30: Initial Price | G30: Initial Cost | H30: Cash at Liability Date | I30: Annual Coupon Cash | J30: Funding Status
A31: 2024 Liability | B31: ='DATA & ASSUMPTIONS'!D4 -> 45657 | C31: Beta | D31: 1000 | E31: ='DATA & ASSUMPTIONS'!B4/D31 -> 2400 | F31: ='DATA & ASSUMPTIONS'!E16 -> 922.78 | G31: =E31*F31 -> 2214672 | H31: =D31*E31 -> 2400000 | I31: =E31*D31*'DATA & ASSUMPTIONS'!C16 -> 0 | J31: FULLY FUNDED
A32: 2027 Liability | B32: ='DATA & ASSUMPTIONS'!D5 -> 46752 | C32: Delta | D32: 1000 | E32: ='DATA & ASSUMPTIONS'!B5/D32 -> 3600 | F32: ='DATA & ASSUMPTIONS'!E18 -> 986.07 | G32: =E32*F32 -> 3549852 | H32: =D32*E32 -> 3600000 | I32: =E32*D32*'DATA & ASSUMPTIONS'!C18 -> 126000 | J32: FULLY FUNDED
A34: Funding Summary | B34: 2024 Cost | C34: 2027 Cost | D34: Cash Buffer | E34: Total Funding / Reserve | F34: Residual Growth Capital
A35: Candidate A (Beta + Delta) | B35: =G31 -> 2214672 | C35: =G32 -> 3549852 | D35: ='DATA & ASSUMPTIONS'!B25 -> 0 | E35: =SUM(B35:D35) -> 5764524 | F35: ='DATA & ASSUMPTIONS'!B3-E35 -> 6235476
A37: CANDIDATE B - Shorter- Duration Prefunding
A38: Liability | B38: Due Date | C38: Instrument | D38: Face / Unit | E38: Units | F38: Initial Price | G38: Initial Cost | H38: Cash at Liability Date | I38: Annual Coupon Cash | J38: Funding Status
A39: 2024 Liability | B39: ='DATA & ASSUMPTIONS'!D4 -> 45657 | C39: Beta | D39: 1000 | E39: ='DATA & ASSUMPTIONS'!B4/D39 -> 2400 | F39: ='DATA & ASSUMPTIONS'!E16 -> 922.78 | G39: =E39*F39 -> 2214672 | H39: =D39*E39 -> 2400000 | I39: =D39*E39*'DATA & ASSUMPTIONS'!C16 -> 0 | J39: FULLY FUNDED
A40: 2027 Liability | B40: ='DATA & ASSUMPTIONS'!D5 -> 46752 | C40: Gamma + Cash Reserve | D40: 1000 | E40: =ROUNDUP('DATA & ASSUMPTIONS'!B5/SUM($B$5:$D$5),0) -> 3215 | F40: ='DATA & ASSUMPTIONS'!E17 -> 1002.49 | G40: =E40*F40 -> 3223005.4 | H40: =D40*E40 -> 3215000 | I40: =E40*$F$14 -> 128600 | J40: =IF(H40>='DATA & ASSUMPTIONS'!B5,"FULLY FUNDED","SHORTFALL") -> SHORTFALL
A42: Funding Summary | B42: 2024 Cost | C42: 2027 Cost | D42: Cash Buffer | E42: Total Funding / Reserve | F42: Residual Growth Capital
A43: Candidate B (Beta + Gamma + Cash Reserve) | B43: =G39 -> 2214672 | C43: =G40 -> 3223005.4 | D43: ='DATA & ASSUMPTIONS'!B25 -> 0 | E43: =SUM(B43:D43) -> 5437677.3 | F43: ='DATA & ASSUMPTIONS'!B3-E43 -> 6562322.7
A45: CREDIBLE ALTERNATIVE
A46: Criteria | B46: Candidate A | C46: Candidate B | D46: Preferred | E46: Reason
A47: Initial funding cost | B47: =E35 -> 5764524 | C47: =E43 -> 5437677.3 | D47: B | E47: Candidate B requires about $326,847 less initial capital, leaving more funds available for growth.
A48: 2024 contractual coverage | B48: Fully funded | C48: Fully funded | D48: Tie | E48: Both strategies use Beta and fully cover the $2.4m payment due in 2024.
A49: 2027 contractual coverage | B49: =H32 -> 3600000 | C49: =H40 -> 3215000 | D49: A | E49: Both cover the liability, but Candidate A provides the required principal directly at the 2027 liability date, while Candidate B receives the funds earlier and must hold them as cash.
A50: Residual growth capital | B50: =F35 -> 6235476 | C50: =F43 -> 6562322.7 | D50: B | E50: Candidate B leaves about $326,847 more initial capital for the growth portfolio.
...

Sheet RATE RISK & DECISION
A1: DURATION, CONVEXITY, RATE SCENARIOS & FINAL DECISION
A2: KEY OUTPUT | B2: VALUE
A3: 2024 Funding Status | B3: ='BOND & FUNDING ANALYSIS'!J31 -> FULLY FUNDED
A4: 2027 Funding Status | B4: ='BOND & FUNDING ANALYSIS'!J32 -> FULLY FUNDED
A5: Total Funding / Reserve | B5: ='BOND & FUNDING ANALYSIS'!E35 -> 5764524
A6: Residual Growth Capital | B6: ='BOND & FUNDING ANALYSIS'!F35 -> 6235476
A7: Parallel Shock Assumption | B7: ='DATA & ASSUMPTIONS'!B26 -> 0.01
A10: DURATION & CONVEXITY
A11: Bond | B11: Price | C11: YTM | D11: Maturity | E11: Macaulay Duration | F11: Modified Duration | G11: Convexity | H11: Comment
A12: Alpha | B12: ='BOND & FUNDING ANALYSIS'!B12 -> 958.77 | C12: ='BOND & FUNDING ANALYSIS'!G12 -> 0.043003014 | D12: ='BOND & FUNDING ANALYSIS'!E12 -> 1 | E12: =(1*'BOND & FUNDING ANALYSIS'!B3/(1+$C12)^1+2*'BOND & FUNDING ANALYSIS'!C3/(1+$C12)^2+3*'BOND & FUNDING ANALYSIS'!D3/(1+$C12)^3+4*'BOND & FUNDING ANALYSIS'!E3/(1+$C12)^4+5*'BOND & FUNDING ANALYSIS'!F3/(1+$C12)^5+6*'BOND & FUNDING ANALYSIS'!G3/(1+$C12)^6+7*'BOND & FUNDING ANALYSIS'!H3/(1+$C12)^7+8*'BOND & FUNDING ANALYSIS'!I3/(1+$C12)^8)/$B12 -> 1 | F12: =E12/(1+C12) -> 0.95877 | G12: =(1*2*'BOND & FUNDING ANALYSIS'!B3/(1+$C12)^3 +2*3*'BOND & FUNDING ANALYSIS'!C3/(1+$C12)^4 +3*4*'BOND & FUNDING ANALYSIS'!D3/(1+$C12)^5 +4*5*'BOND & FUNDING ANALYSIS'!E3/(1+$C12)^6 +5*6*'BOND & FUNDING ANALYSIS'!F3/(1+$C12)^7 +6*7*'BOND & FUNDING ANALYSIS'!G3/(1+$C12)^8 +7*8*'BOND & FUNDING ANALYSIS'!H3/(1+$C12)^9 +8*9*'BOND & FUNDING ANALYSIS'!I3/(1+$C12)^10)/$B12 -> 1.8384798 | H12: Zero-coupon: duration equals maturity.
A13: Beta | B13: ='BOND & FUNDING ANALYSIS'!B13 -> 922.78 | C13: ='BOND & FUNDING ANALYSIS'!G13 -> 0.041000441 | D13: ='BOND & FUNDING ANALYSIS'!E13 -> 2 | E13: =(1*'BOND & FUNDING ANALYSIS'!B4/(1+$C13)^1+2*'BOND & FUNDING ANALYSIS'!C4/(1+$C13)^2+3*'BOND & FUNDING ANALYSIS'!D4/(1+$C13)^3+4*'BOND & FUNDING ANALYSIS'!E4/(1+$C13)^4+5*'BOND & FUNDING ANALYSIS'!F4/(1+$C13)^5+6*'BOND & FUNDING ANALYSIS'!G4/(1+$C13)^6+7*'BOND & FUNDING ANALYSIS'!H4/(1+$C13)^7+8*'BOND & FUNDING ANALYSIS'!I4/(1+$C13)^8)/$B13 -> 2 | F13: =E13/(1+C13) -> 1.9212288 | G13: =(1*2*'BOND & FUNDING ANALYSIS'!B4/(1+$C13)^3 +2*3*'BOND & FUNDING ANALYSIS'!C4/(1+$C13)^4 +3*4*'BOND & FUNDING ANALYSIS'!D4/(1+$C13)^5 +4*5*'BOND & FUNDING ANALYSIS'!E4/(1+$C13)^6 +5*6*'BOND & FUNDING ANALYSIS'!F4/(1+$C13)^7 +6*7*'BOND & FUNDING ANALYSIS'!G4/(1+$C13)^8 +7*8*'BOND & FUNDING ANALYSIS'!H4/(1+$C13)^9 +8*9*'BOND & FUNDING ANALYSIS'!I4/(1+$C13)^10)/$B13 -> 5.53668 | H13: Zero-coupon candidate for 2024 liability.
A14: Gamma | B14: ='BOND & FUNDING ANALYSIS'!B14 -> 1002.49 | C14: ='BOND & FUNDING ANALYSIS'!G14 -> 0.039104257 | D14: ='BOND & FUNDING ANALYSIS'!E14 -> 3 | E14: =(1*'BOND & FUNDING ANALYSIS'!B5/(1+$C14)^1+2*'BOND & FUNDING ANALYSIS'!C5/(1+$C14)^2+3*'BOND & FUNDING ANALYSIS'!D5/(1+$C14)^3+4*'BOND & FUNDING ANALYSIS'!E5/(1+$C14)^4+5*'BOND & FUNDING ANALYSIS'!F5/(1+$C14)^5+6*'BOND & FUNDING ANALYSIS'!G5/(1+$C14)^6+7*'BOND & FUNDING ANALYSIS'!H5/(1+$C14)^7+8*'BOND & FUNDING ANALYSIS'!I5/(1+$C14)^8)/$B14 -> 2.8862478 | F14: =E14/(1+C14) -> 2.7776306 | G14: =(1*2*'BOND & FUNDING ANALYSIS'!B5/(1+$C14)^3 +2*3*'BOND & FUNDING ANALYSIS'!C5/(1+$C14)^4 +3*4*'BOND & FUNDING ANALYSIS'!D5/(1+$C14)^5 +4*5*'BOND & FUNDING ANALYSIS'!E5/(1+$C14)^6 +5*6*'BOND & FUNDING ANALYSIS'!F5/(1+$C14)^7 +6*7*'BOND & FUNDING ANALYSIS'!G5/(1+$C14)^8 +7*8*'BOND & FUNDING ANALYSIS'!H5/(1+$C14)^9 +8*9*'BOND & FUNDING ANALYSIS'!I5/(1+$C14)^10)/$B14 -> 10.552827 | H14: Coupon bond; intermediate curve information.
A15: Delta | B15: ='BOND & FUNDING ANALYSIS'!B15 -> 986.07 | C15: ='BOND & FUNDING ANALYSIS'!G15 -> 0.038112483 | D15: ='BOND & FUNDING ANALYSIS'!E15 -> 5 | E15: =(1*'BOND & FUNDING ANALYSIS'!B6/(1+$C15)^1+2*'BOND & FUNDING ANALYSIS'!C6/(1+$C15)^2+3*'BOND & FUNDING ANALYSIS'!D6/(1+$C15)^3+4*'BOND & FUNDING ANALYSIS'!E6/(1+$C15)^4+5*'BOND & FUNDING ANALYSIS'!F6/(1+$C15)^5+6*'BOND & FUNDING ANALYSIS'!G6/(1+$C15)^6+7*'BOND & FUNDING ANALYSIS'!H6/(1+$C15)^7+8*'BOND & FUNDING ANALYSIS'!I6/(1+$C15)^8)/$B15 -> 4.6704108 | F15: =E15/(1+C15) -> 4.4989448 | G15: =(1*2*'BOND & FUNDING ANALYSIS'!B6/(1+$C15)^3 +2*3*'BOND & FUNDING ANALYSIS'!C6/(1+$C15)^4 +3*4*'BOND & FUNDING ANALYSIS'!D6/(1+$C15)^5 +4*5*'BOND & FUNDING ANALYSIS'!E6/(1+$C15)^6 +5*6*'BOND & FUNDING ANALYSIS'!F6/(1+$C15)^7 +6*7*'BOND & FUNDING ANALYSIS'!G6/(1+$C15)^8 +7*8*'BOND & FUNDING ANALYSIS'!H6/(1+$C15)^9 +8*9*'BOND & FUNDING ANALYSIS'!I6/(1+$C15)^10)/$B15 -> 25.402287 | H15: Candidate for 2027 liability.
A16: Epsilon | B16: ='BOND & FUNDING ANALYSIS'!B16 -> 1040.71 | C16: ='BOND & FUNDING ANALYSIS'!G16 -> 0.038978901 | D16: ='BOND & FUNDING ANALYSIS'!E16 -> 8 | E16: =(1*'BOND & FUNDING ANALYSIS'!B7/(1+$C16)^1+2*'BOND & FUNDING ANALYSIS'!C7/(1+$C16)^2+3*'BOND & FUNDING ANALYSIS'!D7/(1+$C16)^3+4*'BOND & FUNDING ANALYSIS'!E7/(1+$C16)^4+5*'BOND & FUNDING ANALYSIS'!F7/(1+$C16)^5+6*'BOND & FUNDING ANALYSIS'!G7/(1+$C16)^6+7*'BOND & FUNDING ANALYSIS'!H7/(1+$C16)^7+8*'BOND & FUNDING ANALYSIS'!I7/(1+$C16)^8)/$B16 -> 6.9181656 | F16: =E16/(1+C16) -> 6.6586199 | G16: =(1*2*'BOND & FUNDING ANALYSIS'!B7/(1+$C16)^3 +2*3*'BOND & FUNDING ANALYSIS'!C7/(1+$C16)^4 +3*4*'BOND & FUNDING ANALYSIS'!D7/(1+$C16)^5 +4*5*'BOND & FUNDING ANALYSIS'!E7/(1+$C16)^6 +5*6*'BOND & FUNDING ANALYSIS'!F7/(1+$C16)^7 +6*7*'BOND & FUNDING ANALYSIS'!G7/(1+$C16)^8 +7*8*'BOND & FUNDING ANALYSIS'!H7/(1+$C16)^9 +8*9*'BOND & FUNDING ANALYSIS'!I7/(1+$C16)^10)/$B16 -> 54.785467 | H16: Longer maturity; highest rate sensitivity among case bonds.
A19: PARALLEL RATE SHOCK
A20: Bond | B20: Base Price | C20: Base YTM | D20: Shock | E20: Approx ΔP/P | F20: Approx Price | G20: Exact Shocked Price | H20: Exact ΔP/P | I20: Approx Error | J20: Liability Role | K20: Funding Interpretation
A21: Beta | B21: =B13 -> 922.78 | C21: =C13 -> 0.041000441 | D21: ='DATA & ASSUMPTIONS'!B26 -> 0.01 | E21: =-F13*D21+0.5*G13*D21^2 -> -0.018935454 | F21: =B21*(1+E21) -> 905.30674 | G21: ='BOND & FUNDING ANALYSIS'!B4/(1+C21+D21)^1 +'BOND & FUNDING ANALYSIS'!C4/(1+C21+D21)^2 +'BOND & FUNDING ANALYSIS'!D4/(1+C21+D21)^3 +'BOND & FUNDING ANALYSIS'!E4/(1+C21+D21)^4 +'BOND & FUNDING ANALYSIS'!F4/(1+C21+D21)^5 +'BOND & FUNDING ANALYSIS'!G4/(1+C21+D21)^6 +'BOND & FUNDING ANALYSIS'!H4/(1+C21+D21)^7 +'BOND & FUNDING ANALYSIS'!I4/(1+C21+D21)^8 -> 905.30351 | H21: =G21/B21-1 -> -0.018938957 | I21: =E21-H21 -> 3.5036536e-06 | J21: 2024 principal | K21: Market value can change before maturity; contractual principal remains the key liability-funding test if held to maturity and no default.
A22: Delta | B22: =B15 -> 986.07 | C22: =C15 -> 0.038112483 | D22: ='DATA & ASSUMPTIONS'!B26 -> 0.01 | E22: =-F15*D22+0.5*G15*D22^2 -> -0.043719334 | F22: =B22*(1+E22) -> 942.95968 | G22: ='BOND & FUNDING ANALYSIS'!B6/(1+C22+D22)^1 +'BOND & FUNDING ANALYSIS'!C6/(1+C22+D22)^2 +'BOND & FUNDING ANALYSIS'!D6/(1+C22+D22)^3 +'BOND & FUNDING ANALYSIS'!E6/(1+C22+D22)^4 +'BOND & FUNDING ANALYSIS'!F6/(1+C22+D22)^5 +'BOND & FUNDING ANALYSIS'!G6/(1+C22+D22)^6 +'BOND & FUNDING ANALYSIS'!H6/(1+C22+D22)^7 +'BOND & FUNDING ANALYSIS'!I6/(1+C22+D22)^8 -> 942.93238 | H22: =G22/B22-1 -> -0.043747018 | I22: =E22-H22 -> 2.7683826e-05 | J22: 2027 principal | K22: Market value can change before maturity; contractual principal remains the key liability-funding test if held to maturity and no default.
A25: CURVE-SHAPE SCENARIO
A26: Bond | B26: Base YTM | C26: Curve Shock | D26: Shocked YTM | E26: Base Price | F26: Exact Shocked Price | G26: Price Change | H26: Liability Date | I26: Interpretation
A27: Beta | B27: ='BOND & FUNDING ANALYSIS'!G13 -> 0.041000441 | C27: ='DATA & ASSUMPTIONS'!B27 -> 0.005 | D27: =B27+C27 -> 0.046000441 | E27: =B13 -> 922.78 | F27: ='BOND & FUNDING ANALYSIS'!B4/(1+$D27)^1 +'BOND & FUNDING ANALYSIS'!C4/(1+$D27)^2 +'BOND & FUNDING ANALYSIS'!D4/(1+$D27)^3 +'BOND & FUNDING ANALYSIS'!E4/(1+$D27)^4 +'BOND & FUNDING ANALYSIS'!F4/(1+$D27)^5 +'BOND & FUNDING ANALYSIS'!G4/(1+$D27)^6 +'BOND & FUNDING ANALYSIS'!H4/(1+$D27)^7 +'BOND & FUNDING ANALYSIS'!I4/(1+$D27)^8 -> 913.9791 | G27: =F27/E27-1 -> -0.0095373759 | H27: 45657 | I27: Shock affects mark-to-market value; check whether contractual maturity cash still covers the due payment.
A28: Delta | B28: ='BOND & FUNDING ANALYSIS'!G15 -> 0.038112483 | C28: ='DATA & ASSUMPTIONS'!B28 -> -0.005 | D28: =B28+C28 -> 0.033112483 | E28: =B15 -> 986.07 | F28: ='BOND & FUNDING ANALYSIS'!B6/(1+$D28)^1 +'BOND & FUNDING ANALYSIS'!C6/(1+$D28)^2 +'BOND & FUNDING ANALYSIS'!D6/(1+$D28)^3 +'BOND & FUNDING ANALYSIS'!E6/(1+$D28)^4 +'BOND & FUNDING ANALYSIS'!F6/(1+$D28)^5 +'BOND & FUNDING ANALYSIS'!G6/(1+$D28)^6 +'BOND & FUNDING ANALYSIS'!H6/(1+$D28)^7 +'BOND & FUNDING ANALYSIS'!I6/(1+$D28)^8 -> 1008.568 | G28: =F28/E28-1 -> 0.022815814 | H28: 46752 | I28: Shock affects mark-to-market value; check whether contractual maturity cash still covers the due payment.
A31: INITIAL DECISION RECORD
A32: Decision Item | B32: Recommended / Current | C32: Key Number | D32: Rationale
A33: 2024 Funding | B33: 2,400 Beta zero-coupon bonds | C33: ='BOND & FUNDING ANALYSIS'!G31 -> 2214672 | D33: Directly matches 31-Dec-2024 principal need.
A34: 2027 Funding | B34: 3,600 Delta bonds | C34: ='BOND & FUNDING ANALYSIS'!G32 -> 3549852 | D34: Delta principal directly matches 31-Dec-2027. All $126,000 annual coupons are retained in the funding sleeve, excluded from initial growth capital, and the $630,000 accumulated reserve becomes unrestricted after the 2027 liability is paid.
A35: Total Funding / Reserve | B35: Candidate A funding + cash buffer | C35: ='BOND & FUNDING ANALYSIS'!E35 -> 5764524 | D35: Must reconcile with $12m total fund.
A36: Residual Growth Capital | B36: Pass residual capital to growth sleeve | C36: ='BOND & FUNDING ANALYSIS'!F35 -> 6235476 | D36: Residual capital equals $12m less the initial cost of the liability-funding sleeve.
A37: Initial Funding Strategy | B37: Candidate A - Maturity - Matched Beta + Delta | C37: Recommended | D37: Candidate B is cheaper and leaves more growth capital, but Candidate A provides better liability-date matching, lower timing/reinvestment risk and simpler implementation.
A38: Formal Approval Status | B38: Recommended by Mem 1; pending group sign-off | C38: $6,235,476 provisional growth capital | D38: Mem 2 may continue analysis with the provisional amount; do not label the allocation 'approved/frozen' until group confirmation.
